<?xml version="1.0"?>
<robot xmlns:xacro="http://ros.org/wiki/xacro">
  <xacro:include filename="$(find agv_description)/urdf/wheel/wheel.gazebo.xacro" />
  <xacro:include filename="$(find agv_description)/urdf/wheel/wheel.transmission.xacro" />
  <xacro:macro name="wheel" params="prefix parent *joint_origin *joint_axis">
    <joint name="${prefix}_wheel_joint" type="continuous">
      <xacro:insert_block name="joint_origin" />
      <xacro:insert_block name="joint_axis" />
      <parent link="${parent}" />
      <child link="${prefix}_wheel" />
      <limit effort="7" velocity="9" />
      <dynamics damping="0.00001" friction="0.002"/>
    </joint>
    
    <link name="${prefix}_wheel">
      <visual>
        <geometry>
          <cylinder radius="0.03225" length="0.013"/>
        </geometry>
        <material name="black">
          <color rgba="0 0 0 1"/>
        </material>
      </visual>

      <collision>
        <geometry>
          <cylinder radius="0.03225" length="0.013"/>
        </geometry>
      </collision>
      
      <inertial>
        <origin xyz="0.0 0.0 0.0" />
        <mass value="0.300"/>
        <inertia ixx="8.222968749999999e-05" ixy="0" ixz="0" iyy="8.222968749999999e-05" iyz="0" izz="0.000156009375"/>
      </inertial>
    </link>
  </xacro:macro>
</robot>